Workbook

Sheet How to Use
B1: HOW TO USE THIS WORKBOOK
B3: STRUCTURE
B4: One master sheet - 'Use Case Library' - contains all 46 defence use cases with full detail. Policy sheets pull from it automatically via INDEX/MATCH. One input (UC ID in yellow cell) drives all lookups.
B6: ADDING A NEW POLICY (3 steps)
B7: 1. Right-click 'Policy - TEMPLATE' tab → Move or Copy → tick 'Create a copy'. Rename to 'Policy - UC-XXX'.
B8: 2. Type the UC ID in the yellow cell. All context auto-fills.
B9: 3. Fill in Decision Logic, Metrics, Edge Cases, Test Cases, and Sign-off manually.
B11: ADDING A NEW USE CASE
B12: Add a row in the Use Case Library after the appropriate group separator. Use the same column structure. Then create a policy sheet for it when ready.
B14: COLOUR CODING
B15: Group separator rows are colour-coded by domain. The Detection Modality column is colour-coded: green = Visual Only, amber = Visual-Primary Audio-Enhanced, red = Visual + Audio (required). The Modality Summary sheet provides a full breakdown.
B17: SMART LINKING
... B24: • Foundation use cases (UC-006, UC-008, UC-045) should be prioritised first - many others depend on them.

Sheet Use Case Library
A1: Status | B1: UC ID | C1: Group | D1: Category | E1: Use Case Name | F1: Description | G1: User Intent | H1: Trigger / Detection Method | I1: Key Behaviours to Track | J1: Desired Outcome | K1: Current Handling | L1: Edge Cases / Failure Modes | M1: Priority | N1: Policy / Algorithm Status | O1: Policy / Algorithm Summary | P1: Dependencies | Q1: Config Variables | R1: Detection Modality | S1: Modality Rationale | T1: Policy Sheet
B2: GROUP A: CORE SAFETY
A3: TRUE | B3: UC-001 | C3: A | D3: Core Safety | E3: Weapon Muzzle Direction Violation (Flagging) | F3: Detects when a weapon muzzle sweeps across another person or points in an unsafe direction relative to the designated firing arc. Must distinguish momentary transitions (low-ready to firing position) from sustained unsafe orientation. | G3: Never point your weapon at anything you don't intend to shoot - the most fundamental range safety rule. | H3: Pose estimation of firer + weapon orientation vector relative to other detected persons and safe arc boundaries. | I3: 1) Muzzle-to-person angular proximity 2) Duration of unsafe orientation (transient vs sustained) 3) Frequency per individual per session 4) Context: was the firer in motion or stationary? | J3: Immediate visual/audible alert to range safety officer with camera snapshot and firer location. By default: If no external system integration is needed, it will then route the notification and alert to Accel. | K3: Generic post-event review of CCTV - violations discovered after the fact, if at all. | L3: - Momentary sweep during weapon transition - Multiple people in frame - which is 'swept'? - Weapon with mounted optic obscures muzzle line - Prone position makes muzzle direction harder to resolve | M3: P0 - Critical | N3: Not Started | O3: Weapon Muzzle Direction Violation IF muzzle-to-person angle < 15° AND duration > 2s → ALERT (sustained sweep). IF angle < 15° AND duration ≤ 2s → LOG as transient. IF firer in motion (transitioning stance) → suppress alert, log only. Repeated transients (≥3 in session) → escalate to pattern alert via UC-010 | R3: Visual Only | S3: Weapon orientation vector is fully observable from visual pose estimation. No audio needed.
A4: TRUE | B4: UC-002 | C4: A | D4: Core Safety | E4: Unauthorized Person in Danger Zone | F4: Detects a human figure entering a designated danger zone or downrange area while the (live/simulated) range is in operation. Could be a range worker, lost individual, or animal false positive. | G4: Prevent any person from being in the impact area or danger zone during (live/simulated) fire. | H4: Person detection (human body classifier) + geofenced zone overlay on camera feed + range status integration (hot/cold). Focus on both day and night modes. | I4: 1) Detection confidence score 2) Time from zone entry (seen on camera) to alert (latency) 3) False positive rate (animals, shadows, vegetation) 4) Distance from nearest active firing point | J4: Immediate range-wide ceasefire recommendation with location overlay and camera feed to range control. By default: If no external system integration is needed, it will then route the notification and alert to Accel. | K4: Physical sentries and range guards with binoculars - limited visibility, fatigue, no night capability. | L4: - Animal intrusion triggering false alert - Heat shimmer / mirage causing phantom detections - Authorised range party in zone during brief ceasefire windows - Person partially occluded by terrain | M4: P0 - Critical | N4: Not Started | O4: Unauthorized Person in Danger Zone IF human detected in geofenced danger zone AND range status = HOT → immediate CEASEFIRE RECOMMENDATION to range control. IF confidence < 0.7 → flag for human verification before ceasefire call. IF entity classified as animal → LOG, no ceasefire. IF range status = COLD → LOG as administrative entry, no alert. | P4: UC-006, UC-027 | R4: Visual Only | S4: Human figure detection in a geofenced zone is well-established visual analytics. No audio needed.
A5: TRUE | B5: UC-003 | C5: A | D5: Core Safety | E5: Weapon Left Unattended Detection | F5: Detects a weapon stationary and not associated with any person in proximity - on ground, bench, or firing point with no one nearby - beyond a defined time threshold. | G5: No weapon should ever be left unsecured and unattended on a range. | H5: Weapon-shaped object detection + human proximity check within defined radius + time-based trigger (e.g., 30s with no person within 2m). Focus on both day and night modes. | I5: 1) Time weapon is unattended before detection 2) Distance to nearest person when flagged 3) Location context (firing point vs walkway vs rest area) 4) False positive rate (training props, weapon racks) | J5: Alert to nearest safety officer with weapon location, camera feed, and duration unattended. By default: If no external system integration is needed, it will then route the notification and alert to Accel. | K5: Discovered during physical checks or when someone reports a found weapon. | L5: - Weapons deliberately placed in racks (authorised) - Training props / dummy weapons - Weapon placed down momentarily during drill change - Partial occlusion (under bench, behind bag) | M5: P1 - High | N5: Not Started | O5: Weapon Left Unattended IF weapon detected with no person within 2m radius for > 30s → ALERT to nearest safety officer. IF weapon is in designated rack/storage zone → suppress (authorised placement). IF weapon unattended > 120s anywhere → escalate to URGENT. Reset timer when any person enters 2m radius. | P5: UC-008 | R5: Visual Only | S5: Weapon detection + proximity analysis is fully visual. Time-based logic is system-side.
A6: TRUE | B6: UC-004 | C6: A | D6: Core Safety | E6: Negligent / Accidental Discharge Detection | F6: Detects weapon discharge outside designated firing window or when range status is ceasefire/safe. Must distinguish actual discharge from camera artifacts. | G6: Any unplanned discharge is a serious safety incident requiring immediate investigation. | H6: Muzzle flash detection (1-2 frames) + recoil signature + ACOUSTIC GUNSHOT DETECTION for confirmation. Visual alone insufficient in daylight. Focus on both day and night modes. Necessary to consider audio cue from the live environment - adopt this as one of the primary verification layers. | I6: 1) Detection confidence (visual-only vs audio-confirmed) 2) Exact timestamp and location 3) Range status at time of discharge 4) Direction of discharge relative to safe arc 5) Attribution: which position fired | J6: Immediate alert with multi-modal confirmation. Auto-log incident. Trigger ceasefire if range was supposed to be safe. The placement location of audio receiver in this case is important. Ensure the audio cue received is clear - this case may need to define the sound decibel to gauge the distance apart. By default: If no external system integration is needed, it will then route the notification and alert to Accel. | K6: Reported verbally by safety officers - delayed, sometimes missed in noisy environments. | L6: - Daylight muzzle flash nearly invisible on camera - Blank rounds: flash but no recoil - Reflected light / camera artifact mimics flash - Suppressed weapons: minimal flash and report - Multiple simultaneous discharges | M6: P0 - Critical | N6: Not Started | O6: Negligent / Accidental Discharge IF acoustic gunshot detected AND range status ≠ HOT → CRITICAL ALERT + auto-log incident. IF acoustic detected AND range status = HOT but outside firing window → ALERT. IF visual muzzle flash only (no acoustic confirm) → flag as UNCONFIRMED, request human verification. Always capture ±10s multi-camera footage around event timestamp. | P6: UC-008, UC-026 | R6: Visual + Audio | S6: AUDIO CRITICAL. Muzzle flash often invisible in daylight (1-2 frames). Acoustic gunshot detection provides reliable trigger; video provides attribution.
A7: TRUE | B7: UC-005 | C7: A | D7: Core Safety | E7: Post-Firing Weapon Clearing Verification | F7: After ceasefire, visually monitors each firer performing clearing drill - magazine removal, bolt lock, chamber inspection - flags skipped or incorrect steps. | G7: Verify every weapon is made safe before anyone moves from firing position. | H7: Action sequence recognition: detect magazine removal → bolt manipulation → chamber check → show-clear gesture. Take note for night mode, where it can be dark, IR camera need to be considered. | I7: 1) Clearing steps completed per individual 2) Steps skipped or out of order 3) Time from ceasefire to clearing complete 4) Individuals who walk away without clearing | J7: Checklist overlay per firing position. Flag incomplete clearings before range declared safe. By default: If no external system integration is needed, it will then route the notification and alert to Accel. | K7: Safety officer walks the line - slow, can miss detail with many firers. | L7: - Belt-fed weapons have different clearing sequence - Pistols cleared differently than long arms - Body occludes weapon manipulation from certain angles - Speed of manipulation hard to resolve at standard frame rates | M7: P0 - Critical | N7: Not Started | O7: Post-Firing Weapon Clearing Verification On CEASEFIRE event, initiate per-position monitoring. FOR EACH firer: track clearing sequence [magazine remove → bolt lock → chamber check → show-clear]. IF any step skipped → FLAG position as INCOMPLETE. IF firer leaves position before all steps confirmed → URGENT ALERT. Range not declared SAFE until all positions show COMPLETE. | P7: UC-008, UC-006 | R7: Visual Only | S7: Clearing is a sequence of visible physical actions. Fully observable from visual analytics.
A8: TRUE | B8: UC-006 | C8: A | D8: Core Safety | E8: Personnel Count and Position Reconciliation | F8: Continuously counts and maps all personnel against expected manifest. Detects: missing person, extra person, person in wrong position. | G8: Know where every person on the range is at all times. | H8: Multi-camera person detection + position mapping + manifest comparison. | I8: 1) Count accuracy vs manifest 2) Position accuracy (correct lane/zone) 3) Time to detect discrepancy 4) Resilience to occlusion and grouping | J8: Real-time personnel map in range control. Instant alert on count mismatch or position deviation. By default: If no external system integration is needed, it will then route the notification and alert to Accel. | K8: Manual headcount at start and end of serials - no continuous tracking. | L8: - Identical uniforms and gear - Clustering makes count difficult - Camera blind spots - People entering/exiting buildings or vehicles | M8: P0 - Critical | N8: Not Started | O8: Personnel Count and Position Reconciliation On exercise start, lock manifest count. Continuous count at 5s intervals. IF count < manifest → MISSING PERSON alert (P0). IF count > manifest → EXTRA PERSON alert. IF individual deviates > 10m from assigned position → POSITION DEVIATION warning. Reconcile against UC-035 entry/exit log for discrepancy resolution. | P8: UC-045, UC-035 | R8: Visual Only | S8: Person detection and counting is mature visual analytics. Foundation use case for many others.
A9: TRUE | B9: UC-007 | C9: A | D9: Core Safety | E9: Firing Line Breach Detection | F9: Detects when any person moves forward of the firing line during live-fire serial. Even partial step counts. | G9: No person forward of the firing line while weapons are firing. | H9: Person detection + firing line boundary definition in camera frame. Track foot position relative to line. | I9: 1) Detection latency from breach to alert 2) Severity: partial step vs full breach 3) Distance forward of line 4) False positive rate from parallax | J9: Immediate alert. Automatic ceasefire recommendation if breach exceeds threshold. By default: If no external system integration is needed, it will then route the notification and alert to Accel. | K9: Range safety officer watches - can miss peripheral breaches. | L9: - Firing line not physically marked (field firing) - Camera angle makes position ambiguous - Person drops object forward and reaches - Line changes between serials | M9: P0 - Critical | N9: Not Started | O9: Firing Line Breach Detection IF any person's foot position crosses firing line boundary AND range status = HOT → IMMEDIATE ALERT + ceasefire recommendation. IF breach < 0.5m and < 1s (momentary lean) → LOG as minor, no ceasefire. IF breach > 1m or sustained > 2s → CRITICAL, auto-recommend ceasefire. Update line boundary definition at each serial change. | P9: UC-006 | R9: Visual Only | S9: Line boundary + person position is straightforward visual detection.
A10: TRUE | B10: UC-008 | C10: A | D10: Core Safety | E10: Weapon Readiness State Classification | F10: Classifies observable weapon state: holstered/slung, low-ready, high-ready, aimed/shouldered, firing. Feeds into other use cases. | G10: Continuous awareness of weapon states across the range. | H10: Weapon detection + pose classification. Multi-class: slung, low-ready, high-ready, aimed, firing. | I10: 1) Classification accuracy per state 2) State transition detection speed 3) Accuracy across weapon types 4) Robustness to occlusion from gear | J10: Real-time weapon state overlay. Anomaly detection: aimed during ceasefire, firing outside window. | K10: No automated tracking - entirely dependent on safety officer observation. | L10: - Weapon partially hidden by body armour - Pistol states subtler than rifle - Slung weapon bouncing mimics state change - Night/IR conditions alter appearance | M10: P1 - High | N10: Not Started | O10: Weapon Readiness State Classification Continuous classification per tracked individual: SLUNG → LOW-READY → HIGH-READY → AIMED → FIRING. IF state = AIMED and range status ≠ HOT → ALERT. IF state = AIMED and firer not at designated firing position → ALERT. Feed state data to UC-001 (muzzle direction uses weapon state as input) and UC-004 (firing state outside window). | P10: UC-001, UC-004, UC-005 | R10: Visual Only | S10: Weapon state is defined by visible physical configuration. Visual pose classification task.
A11: TRUE | B11: UC-009 | C11: A | D11: Core Safety | E11: Medical Casualty Detection During Live Exercise | F11: Detects person falling, collapsing, or exhibiting distress postures while weapons are in play. Must distinguish genuine event from tactical movement. | G11: Get medical help immediately, even when live fire creates access challenges. Especially critical when the casualty personnel is alone - often overlooked. | H11: Fall detection (sudden vertical-to-horizontal) + stationary posture duration + context analysis. | I11: 1) Time from collapse to detection 2) False positive rate (going prone intentionally vs fall) 3) Distinguishing tactical prone from distress 4) Context: expected vs unexpected posture for exercise phase | J11: Immediate alert to safety officer and medical team. Ceasefire recommendation for affected lane. By default: If no external system integration is needed, it will then route the notification and alert to Accel. | K11: Buddy or adjacent firer notices - delayed, sometimes missed during intense firing. | L11: - Going prone is normal firing position - Simulated casualties in training - Person resting between serials - Gradual event (heat exhaustion) vs sudden collapse | M11: P0 - Critical | N11: Not Started | O11: Medical Casualty Detection IF sudden vertical-to-horizontal transition detected AND person remains stationary > 10s AND context ≠ expected prone position → MEDICAL ALERT to safety officer + medical team. IF audio detects 'man down' call → bypass 10s wait, alert immediately. IF exercise phase expects prone firing → raise stationary threshold to 30s. Always recommend lane-specific ceasefire, not range-wide. | P11: UC-006, UC-004 | R11: Visual-Primary, Audio-Enhanced | S11: VISUAL-PRIMARY: Fall and posture detection are visual. AUDIO-ENHANCED: 'Man down' calls and sudden silence provide secondary confirmation.
A12: TRUE | B12: UC-010 | C12: A | D12: Core Safety | E12: Unsafe Weapon Handling Behaviour Pattern Detection | F12: Identifies accumulated patterns of unsafe behaviour over time - repeated muzzle sweeps, finger on trigger while not firing, weapon manipulation during briefings. Trend indicates intervention needed. | G12: Identify individuals developing unsafe habits before an incident occurs. | H12: Aggregation of detections from UC-001, UC-008, UC-005 over time per individual. Statistical pattern analysis. | I12: 1) Minor violations per individual per session 2) Trend over multiple sessions 3) Correlation between patterns and incident proximity 4) False pattern rate | J12: Flagged report to safety officer with evidence. Recommendation for remedial training. By default: If no external system integration is needed, it will then route the notification and alert to Accel. | K12: Anecdotal - no systematic tracking. | L12: - New trainees expected to have more violations - Cultural differences between units - Pattern window: how far back to look? - Privacy/fairness concerns | M12: P2 - Medium | N12: Not Started | O12: Unsafe Weapon Handling Behaviour Pattern Aggregate violations from UC-001, UC-005, UC-008 per individual per session. IF minor violations ≥ 3 in single session → INTERVENTION ADVISORY to safety officer. IF violations trending upward across sessions (≥2 consecutive sessions above baseline) → REMEDIAL TRAINING recommendation. Weight recent violations higher. Exclude first-session trainees from trend analysis (learning curve allowance). | P12: UC-001, UC-008, UC-005 | R12: Visual Only | S12: Meta-analysis of visual detections aggregated over time. No audio needed.
B13: GROUP B: VEHICLE & MOUNTED SYSTEMS
A14: FALSE | B14: UC-011 | C14: B | D14: Vehicle & Mounted Systems | E14: Vehicle Turret Orientation Safety Monitoring | F14: Tracks turret/gun barrel direction and detects traversal into restricted arc - toward friendly positions, infrastructure, or adjacent lanes. | G14: Vehicle-mounted weapons engage at greater range - unsafe arcs have larger consequences. | H14: Vehicle detection + turret/barrel angle estimation relative to vehicle heading + safe arc overlay based on position. | I14: 1) Turret angle accuracy 2) Time in restricted arc 3) Alert latency 4) Accuracy across vehicle types | J14: Alert to vehicle crew and range control. Turret orientation overlay on range map. | K14: External safety officer from observation tower - limited angle, fatigue. | L14: - Turret sweeps restricted arc during target acquisition - Moving vehicle changes safe arcs continuously - Dust/smoke obscures turret - Multiple vehicles with overlapping arcs | M14: P0 - Critical | N14: Not Started | P14: UC-012 | R14: Visual Only | S14: Turret/barrel orientation is a clearly visible geometric feature. Fully visual.
A15: FALSE | B15: UC-012 | C15: B | D15: Vehicle & Mounted Systems | E15: Vehicle Breach of Designated Movement Corridor | F15: Detects vehicle deviation from designated route or lane. Vehicles straying risk entering impact areas or other active lanes. | G15: Vehicles move fast and take longer to stop - early deviation detection is critical. | H15: Vehicle detection + tracking + geofenced corridor overlay. | I15: 1) Distance of deviation 2) Speed at deviation 3) Duration outside corridor 4) Direction (toward impact area = higher severity) | J15: Alert to vehicle crew and range control with predicted path. | K15: Observation tower spots deviation and radios - often after significant deviation. | L15: - Curves cause natural swing wide - Dust cloud obscures position - Multiple vehicles - which deviated? - Corridor not physically marked | M15: P0 - Critical | N15: Not Started | P15: UC-011, UC-015 | R15: Visual Only | S15: Vehicle tracking against geofenced boundaries is standard visual analytics.
A16: FALSE | B16: UC-013 | C16: B | D16: Vehicle & Mounted Systems | E16: Crew Exposure During Vehicle Live-Fire | F16: Detects personnel with body parts exposed from hatches during vehicle weapon firing when crew should be buttoned up. | G16: Exposed crew during vehicle firing risk injury from blast, casings, or return fire. | H16: Human presence detection at hatch positions during firing events. Classify: closed, partially open, head exposed, torso exposed. | I16: 1) Exposure classification accuracy 2) Correlation with firing events 3) False positives from hatch-mounted equipment 4) Detection at range | J16: Alert to vehicle commander and range control. | K16: External safety staff from distance - very difficult to see hatch status from towers. | L16: - Commander legitimately observing between serials - Hatch open for ventilation, no person exposed - Camera can't see far-side hatches - Vehicle at distance reduces resolution | M16: P1 - High | N16: Not Started | P16: UC-011, UC-004 | R16: Visual Only | S16: Human body detection at hatch openings is visual.
A17: FALSE | B17: UC-014 | C17: B | D17: Vehicle & Mounted Systems | E17: Vehicle-Dismount Safety Proximity Detection | F17: Monitors proximity of dismounted personnel to vehicles during combined arms exercises. Detects soldiers within vehicle danger zones. | G17: Personnel near vehicles during live-fire or maneuver are at risk from blast, movement, and turret rotation. | H17: Person detection + vehicle detection + proximity measurement + danger zone modeling. | I17: 1) Minimum person-vehicle distance 2) Time in danger zone 3) Context: vehicle stationary vs moving, firing vs not 4) Alert response time | J17: Alert to vehicle crew and dismounted personnel via safety officer. | K17: Verbal safety briefs and buddy checks - relies on individual awareness. | L17: - Designated mount/dismount points require proximity - Infantry using vehicle as cover - Vehicle reversing into dismounted position - Danger zone changes with turret rotation | M17: P1 - High | N17: Not Started | P17: UC-006, UC-011 | R17: Visual Only | S17: Person-vehicle proximity is spatial measurement from visual detection.
A18: FALSE | B18: UC-015 | C18: B | D18: Vehicle & Mounted Systems | E18: Vehicle Speed Estimation on Range Roads | F18: Estimates vehicle speed from video and flags speed limit exceedances. Speeding is a common cause of non-combat training injuries. | G18: Enforce speed limits on range roads to prevent vehicle accidents. | H18: Vehicle tracking + calibrated camera geometry + speed from displacement over time. | I18: 1) Speed estimation accuracy (±km/h) 2) False positive rate from parallax 3) Consistency across camera angles 4) Performance in poor visibility | J18: Speed alert to range control. Logged for pattern analysis. | K18: Occasional speed gun checks - infrequent, not continuous. | L18: - Oblique angles distort distance estimation - Dust trail obscures vehicle centroid - Convoy vehicles close together confuse tracking - Calibration drift from camera movement | M18: P2 - Medium | N18: Not Started | P18: UC-012 | R18: Visual Only | S18: Speed estimation from calibrated video is mature visual analytics.
B19: GROUP C: FORMATION & GROUP BEHAVIOUR
A20: TRUE | B20: UC-016 | C20: C | D20: Formation & Group Behaviour | E20: Assault Formation Spacing Violation | F20: Monitors spacing between individuals in tactical formations. Flags when spacing falls outside prescribed standards - too tight or too spread. | G20: Correct spacing is both tactical skill and safety requirement during live-fire movement. | H20: Multi-person detection + inter-person distance measurement + exercise-defined standards. | I20: 1) Average spacing vs standard 2) Min/max deviations 3) Duration of violations 4) Consistently non-compliant individuals | J20: Training feedback spacing heatmap. Real-time alert only if spacing creates safety risk. | K20: Instructor observation - subjective, can only watch part of formation. | L20: - Terrain forces temporary spacing changes - Formation type changes mid-exercise - Smoke/dust reduces visibility - Overlapping personnel from camera angle | M20: P2 - Medium | N20: Not Started | P20: UC-006 | R20: Visual Only | S20: Inter-person distance measurement is straightforward visual analytics.
A21: TRUE | B21: UC-018 | C21: C | D21: Formation & Group Behaviour | E21: Group Bunching Detection at Chokepoints | F21: Detects too many personnel clustering in confined area - doorways, corridors, breach points. Creates tactical failure and real safety risk. | G21: Clustered personnel are vulnerable and create weapon safety risks in confined spaces. | H21: Person density measurement in defined chokepoint zones. Threshold based on zone dimensions and exercise type. | I21: 1) Person count in zone vs maximum 2) Duration of bunching 3) Location frequency (which chokepoints) 4) Correlation with exercise phase | J21: Alert to exercise controller. Training feedback for AAR. | K21: Instructor from outside building - no visibility into chokepoints. | L21: - Controlled stack formation before entry is intentional - Brief transit vs lingering - Camera placement in narrow spaces - Low indoor light | M21: P2 - Medium | N21: Not Started | P21: UC-006, UC-021 | R21: Visual Only | S21: Density counting in a defined zone is visual.
A22: FALSE | B22: UC-019 | C22: C | D22: Formation & Group Behaviour | E22: Friendly Force Crossing Into Opposing Force Zone | F22: In force-on-force exercises, tracks two forces and detects boundary violations - individual from one force enters opposing zone unexpectedly. | G22: Boundary violations can lead to unplanned close-range engagements. | H22: Force identification via visual markers (armbands, helmet bands, IR markers) + zone overlay + crossing detection. | I22: 1) Force marker detection accuracy 2) Boundary crossing frequency 3) Depth of penetration 4) Speed of crossing | J22: Alert to exercise controller and safety staff. Potential exercise pause. | K22: Umpires at boundaries - limited coverage. | L22: - Markers become dirty/obscured - Prisoners or role-players crossing legitimately - Boundary is tactical, not physical - Night exercises: visual markers not visible (need IR) | M22: P1 - High | N22: Not Started | P22: UC-006, UC-043 | R22: Visual Only | S22: Force identification via visual markers and zone detection are visual. IR markers still visual spectrum.
A23: FALSE | B23: UC-020 | C23: C | D23: Formation & Group Behaviour | E23: Observer/Visitor Proximity to Active Exercise | F23: Monitors designated observers, VIPs, or media who must stay in observation areas. Detects drift toward active areas. | G23: Non-participants lack tactical training to understand when they're in danger. | H23: Person detection in observation area + drift tracking. Observers may wear high-vis markers. | I23: 1) Distance from observation boundary 2) Drift speed and direction 3) Time outside designated area 4) Correlation with exercise intensity | J23: Alert to escort / safety officer. | K23: Assigned escort watches - can be distracted with large groups. | L23: - Authorised movement to different observation point - Observer stepping out for phone call - Media with telephoto lenses seeking angles - VIPs who outrank escort and insist on moving closer | M23: P1 - High | N23: Not Started | P23: UC-006, UC-002 | R23: Visual Only | S23: Person tracking in/near zones is standard visual analytics.
B24: GROUP D: URBAN OPERATIONS (MOUT)
A25: FALSE | B25: UC-021 | C25: D | D25: Urban Operations (MOUT) | E25: Room Clearing Sequence Deviation Detection | F25: Tracks movement sequence within rooms during clearing. Flags deviations: missed corners, back-turning to uncleared areas, bunching at doorway. | G25: Correct room clearing is both survival skill and safety requirement with live/blank rounds. | H25: Multi-person indoor tracking + movement vector analysis within room geometry vs expected sequence. | I25: 1) Sequence completion percentage 2) Steps skipped or out of order 3) Time per room vs standard 4) Specific deviations by type | J25: Post-exercise training feedback room-by-room. Real-time alert for safety-critical deviations only. | K25: Instructor from hallway - limited angle, one room at a time. | L25: - Room layouts vary (furniture, obstacles) - Dynamic situations require sequence adaptation - Smoke/flashbang effects obscure camera - Low indoor lighting | M25: P2 - Medium | N25: Not Started | P25: UC-006, UC-018 | R25: Visual-Primary, Audio-Enhanced | S25: VISUAL-PRIMARY: Movement and sequence are visual. AUDIO-ENHANCED: Verbal callouts ('clear left', 'room clear') are integral to the drill.
A26: FALSE | B26: UC-023 | C26: D | D26: Urban Operations (MOUT) | E26: Weapon Discharge in Non-Authorized MOUT Zone | F26: Detects firing activity in rooms/floors designated as no-fire zones - role-player areas, structural damage risk areas. | G26: No-fire zones protect role-players and infrastructure. Any discharge is a serious safety failure. | H26: Muzzle flash detection (more visible indoors) + ACOUSTIC GUNSHOT DETECTION essential for blank rounds. | I26: 1) Detection confidence (visual vs acoustic vs confirmed) 2) Location within building (room-level) 3) Correlation with exercise phase 4) Attribution if possible | J26: Immediate exercise halt for affected building. | K26: Role-players report hearing shots - delayed, sometimes inaccurate. | L26: - Blank rounds: flash but no recoil - hard to detect visually - Indoor echoes complicate acoustic localization - Door slams / simulators mimic gunshots - Flashbang flash vs weapon discharge | M26: P0 - Critical | N26: Not Started | P26: UC-004, UC-025 | R26: Visual + Audio | S26: AUDIO ESSENTIAL indoors. Blank rounds produce minimal visual signature. Acoustic detection reliably captures the report.
A27: TRUE | B27: UC-024 | C27: D | D27: Urban Operations (MOUT) | E27: Stairwell and Elevation Transition Safety Monitoring | F27: Monitors personnel moving between floors with weapons - unsafe muzzle direction, trips/falls, formation breakdowns in vertical transitions. | G27: Stairwells are high-risk for accidental muzzle sweeps and falls with loaded weapons. | H27: Indoor person tracking + weapon orientation estimation in constrained vertical space. | I27: 1) Muzzle violations during stairwell movement 2) Falls or stumbles 3) Formation spacing on stairs 4) Camera coverage quality | J27: Alert for muzzle violations. Training feedback. Safety alert for falls. | K27: No monitoring - stairwells typically unobserved. | L27: - Severe occlusion from tight angles - Weapon position changes rapidly - Low/variable lighting - Brief transit time | M27: P1 - High | N27: Not Started | P27: UC-001, UC-006 | R27: Visual Only | S27: Muzzle direction and fall detection are visual. Challenging camera placement but detection itself needs no audio.
A28: FALSE | B28: UC-025 | C28: D | D28: Urban Operations (MOUT) | E28: Non-Combatant / Role-Player Safety in MOUT | F28: Tracks role-players (civilians, hostages) and monitors proximity to weapon activity. Detects engagement toward role-players or role-players leaving safe positions. | G28: Role-players are real people in a live/blank-fire environment - safety is paramount. | H28: Role-player identification via visual markers + proximity tracking to weapon activity + engagement direction detection. | I28: 1) Min distance between role-player and weapon activity 2) Engagement vectors crossing role-player positions 3) Role-player position stability 4) Time in unplanned proximity | J28: Immediate alert if engagement directed near role-player. Exercise pause if role-player moves to danger. | K28: Role-player self-reports feeling unsafe - after the fact. | L28: - Markers become obscured - Role-player panics and moves unpredictably - Scenario requires role-player near the action - Distinguishing 'near' vs 'at' engagement | M28: P0 - Critical | N28: Not Started | P28: UC-006, UC-001, UC-004 | R28: Visual-Primary, Audio-Enhanced | S28: VISUAL-PRIMARY: Role-player tracking via markers is visual. AUDIO-ENHANCED: Gunshot detection confirms blank fire near role-players.
B29: GROUP E: ENVIRONMENT & INFRASTRUCTURE
A30: FALSE | B30: UC-026 | C30: E | D30: Environment & Infrastructure | E30: Range Flag/Signal Status Detection | F30: Reads visual status of range flags, signal lights, indicator boards and cross-references against range control system. Detects mismatches. | G30: Mismatch between declared status and physical indicators means someone acts on wrong information. | H30: Colour/state classification of flags and lights + range control system data comparison. | I30: 1) Classification accuracy 2) Mismatch detection latency 3) False positives from lighting conditions 4) All flag positions covered by cameras | J30: Immediate alert showing which indicator mismatches. Block status changes until visual confirmation. | K30: Range control declares status and trusts flags are changed - no verification. | L30: - Faded/dirty flags shift colour - Backlighting makes colour ambiguous - Wind wraps flag around pole - Signal lights malfunction | M30: P1 - High | N30: Not Started | P30: UC-004, UC-002 | R30: Visual Only | S30: Colour classification of fixed objects is basic visual analytics.
A31: FALSE | B31: UC-027 | C31: E | D31: Environment & Infrastructure | E31: Downrange Intrusion Detection (Non-Exercise) | F31: Outside active exercise windows, monitors for human, vehicle, or animal activity in impact areas and danger zones. | G31: Impact areas contain UXO and are dangerous even when no firing occurs. | H31: Person/vehicle/animal detection in geofenced zones during non-active periods. 24/7 including IR/thermal. | I31: 1) Detection rate by entity type 2) False positive rate (wildlife) 3) Human vs animal classification accuracy 4) Night/low-light performance | J31: Alert to range control and security. Graduated: animal=log, human=investigate, vehicle=urgent. | K31: Periodic foot patrols and closure signs - large areas, infrequent coverage. | L31: - Wildlife triggers - Heat shimmer phantoms - Authorised maintenance not logged - Terrain obscures ground-level movement | M31: P1 - High | N31: Not Started | P31: UC-002, UC-039 | R31: Visual Only | S31: Perimeter intrusion detection from video is mature. IR/thermal extends to night.
A32: FALSE | B32: UC-028 | C32: E | D32: Environment & Infrastructure | E32: Weather/Visibility Degradation Detection | F32: Monitors visibility from camera feeds - fog, dust, smoke, rain. Flags when visibility drops below exercise threshold. | G32: Reduced visibility changes the safety calculus for different exercise types. | H32: Image quality metrics: contrast ratio, edge detection, visibility distance from known reference points. | I32: 1) Visibility distance accuracy 2) Degradation trend 3) Type (fog vs dust vs smoke) 4) Per-camera status (may be localised) | J32: Alert to range control with assessment. Recommendation to pause/modify if below threshold. | K32: Subjective officer assessment - no objective measurement. | L32: - Localised dust vs general fog - Temporary pyro smoke vs persistent weather - Lens contamination mimics fog - Sun glare mistaken for haze | M32: P2 - Medium | N32: Not Started | P32: UC-043, UC-040 | R32: Visual Only | S32: Visibility assessment from image analysis is well-established.
A33: FALSE | B33: UC-029 | C33: E | D33: Environment & Infrastructure | E33: Target Area Condition Monitoring | F33: Monitors target arrays - detecting fallen, destroyed, moved, or obscured targets. Flags when state doesn't match expected configuration. | G33: Wrong target state means firers may engage wrong area or not engage - safety risk. | H33: Target detection + state classification (up/down/damaged/missing) + comparison against expected config. | I33: 1) State classification accuracy 2) Latency from change to detection 3) Coverage of target area 4) False positives from targets hit during firing (expected) | J33: Alert showing which targets need attention. Pre-exercise verification. | K33: Physical check by target operators - requires ceasefire and personnel downrange. | L33: - Targets hit and falling is expected - Wind-blown vs shot targets - Partial damage (leaning) - Electronic pop-up targets - must track intended state | M33: P2 - Medium | N33: Not Started | P33: UC-026 | R33: Visual Only | S33: Target detection and state classification are visual.
B34: GROUP F: PRE-EXERCISE & ADMINISTRATIVE
A35: TRUE | B35: UC-031 | C35: F | D35: Pre-Exercise & Administrative | E35: PPE Compliance Detection | F35: Verifies all personnel on firing line wearing required PPE - ear protection, eye protection, helmet, body armour. | G35: PPE prevents non-combat injuries from noise, debris, and ricochet. | H35: Object detection on person: ear muffs, eyewear, helmet, body armour. | I35: 1) Detection accuracy per PPE type 2) Known limitations (ear plugs invisible) 3) False positives (sunglasses vs ballistic eyewear) 4) Verified before firing commences | J35: Alert listing non-compliant personnel and missing PPE. | K35: Visual check by safety officer - can miss items with many firers. | L35: - Ear plugs nearly invisible - Ballistic eyewear vs sunglasses - PPE worn improperly (helmet unbuckled, eyewear on forehead) - Body armour under uniform is invisible | M35: P1 - High | N35: Not Started | P35: UC-006 | R35: Visual Only | S35: PPE with distinct silhouettes is visually detectable. Known limitation: ear plugs and concealed items.
A36: TRUE | B36: UC-032 | C36: F | D36: Pre-Exercise & Administrative | E36: Range Briefing Attendance Verification | F36: Headcount and presence verification during mandatory safety briefings. Detects late arrivals, early departures, absentees. | G36: All firers must attend brief - anyone firing without attending is a safety risk. | H36: Person counting in briefing area + duration tracking + manifest comparison. | I36: 1) Headcount accuracy vs manifest 2) Attendance duration per individual 3) Late arrival detection 4) Early departure detection | J36: Attendance log with timestamps. Alert for discrepancies before firing. | K36: Sign-in sheet - easily gamed, no duration verification. | L36: - People at back of briefing area - Open area vs confined room - Brief toilet break and return - Multiple briefings for different serials | M36: P2 - Medium | N36: Not Started | P36: UC-006, UC-035 | R36: Visual Only | S36: Headcount and presence tracking are standard visual analytics.
A37: FALSE | B37: UC-033 | C37: F | D37: Pre-Exercise & Administrative | E37: Weapon Assembly/Disassembly Area Monitoring | F37: Monitors weapon preparation areas for unsafe practices: muzzle violations during assembly, pointing at others, loading in non-designated areas. | G37: Preparation areas are where distracted handling mistakes happen most. | H37: Weapon detection + muzzle direction tracking + activity zone enforcement. | I37: 1) Muzzle violations in preparation area 2) Loading outside designated zone 3) Violation rate comparison between units 4) Time-of-day patterns (fatigue) | J37: Alert to safety supervisor. Unit performance feedback. | K37: Occasional safety officer walk-through - snapshot, not continuous. | L37: - Disassembly means muzzle direction ambiguous - Cleaning involves pointing in various directions - Crowded and occluded areas - Training vs live weapons look identical | M37: P2 - Medium | N37: Not Started | P37: UC-001, UC-008 | R37: Visual Only | S37: Muzzle direction and zone detection are visual analytics.
A38: FALSE | B38: UC-034 | C38: F | D38: Pre-Exercise & Administrative | E38: Ammunition Handling Area Safety Monitoring | F38: Monitors ammunition points for unsafe handling: dropping, incorrect container handling, unauthorised personnel. | G38: Ammunition handling errors can cause injury or loss. | H38: Activity recognition in ammo area + person authorization + handling anomaly detection. | I38: 1) Unauthorised person detections 2) Dropping/mishandling events 3) Container exposure duration 4) Personnel count vs authorised | J38: Alert to ammunition NCO and safety officer. | K38: Ammunition NCO supervises - single point of failure. | L38: - Authorised vs unauthorised personnel distinction - Dropping vs setting down firmly - Ammunition in pockets (invisible) - Temporary field ammo points (no fixed camera) | M38: P2 - Medium | N38: Not Started | P38: UC-006, UC-035 | R38: Visual Only | S38: Activity recognition and zone-based tracking are visual.
A39: TRUE | B39: UC-035 | C39: F | D39: Pre-Exercise & Administrative | E39: Range Access Point Entry/Exit Logging | F39: Logs every person and vehicle entering/exiting. Detects tailgating, non-stopping vehicles, reverse-direction movement. | G39: Accurate entry/exit logging is foundation for knowing who is on the range. | H39: Person/vehicle detection at access points + direction + counting + tailgate detection. | I39: 1) Count accuracy (entry vs exit balance) 2) Tailgate detection rate 3) Vehicle stop compliance 4) Reverse direction alerts | J39: Automatic access log with timestamps and captures. Anomaly alerts. | K39: Guard manually logs - errors, missed entries, illegible records. | L39: - Pedestrians and vehicles at same point - Legitimate convoys vs tailgating - Emergency vehicles bypassing procedure - Poor lighting or weather | M39: P1 - High | N39: Not Started | P39: UC-006, UC-039 | R39: Visual Only | S39: Counting and direction detection at fixed points are mature visual analytics.
B40: GROUP G: POST-EXERCISE & INCIDENT SUPPORT
...

Sheet Column Guide
A1: Column Name | B1: Purpose | C1: How to Fill It | D1: Good Example | E1: Bad Example
A2: UC ID | B2: Unique reference | C2: Sequential: UC-001, UC-002 | D2: UC-001 | E2: 'the safety one'
A3: Group | B3: Letter code for group | C3: A through I | D3: A | E3: (blank)
A4: Category | B4: Domain grouping | C4: From group name | D4: Core Safety | E4: Bad stuff
A5: Use Case Name | B5: Scannable label | C5: Short noun phrase | D5: Weapon Muzzle Direction Violation | E5: Safety issue
A6: Description | B6: Full scope + success | C6: What + what does good look like? | D6: Detects muzzle sweep across persons... | E6: Detect bad things
A7: User Intent | B7: The WHY | C7: Underlying goal | D7: Prevent unsafe muzzle orientation | E7: Keep people safe
A8: Trigger / Detection Method | B8: How the system detects it | C8: Visual method, classifiers, thresholds | D8: Pose estimation + weapon vector + person detection | E8: Camera watches
A9: Key Behaviours to Track | B9: Measurable signals | C9: 3-5 log-reviewable items | D9: Muzzle angle, duration, frequency per person | E9: Track if works
A10: Desired Outcome | B10: Target flow | C10: Detection → response | D10: Immediate alert with snapshot and location | E10: Fix it
A11: Current Handling | B11: Baseline | C11: Honest before state | D11: Post-event CCTV review - after the fact | E11: Fine / N/A
A12: Edge Cases | B12: Failure scenarios | C12: 3-5 boundary conditions | D12: Momentary sweep during transition | E12: (blank)
... A19: Policy Sheet | B19: Link to detail | C19: Auto - hyperlink when policy sheet created | D19: → Policy - UC-001 | E19: (blank = not created)

Sheet Modality Summary
A1: Detection Modality | B1: Count | C1: Implication
A2: Visual Only | B2: 34 | C2: Fully achievable with camera systems. No additional sensor infrastructure.
A3: Visual + Audio | B3: 6 | C3: Requires integrated acoustic sensors. Video alone would miss critical events.
A4: Visual-Primary, Audio-Enhanced | B4: 6 | C4: Functions with video alone but audio significantly improves accuracy or completeness.
A5: TOTAL | B5: 46
A7: USE CASES REQUIRING AUDIO INTEGRATION
A8: UC ID | B8: Use Case Name | C8: Why Audio Is Needed
A9: UC-004 | B9: Negligent / Accidental Discharge Detection | C9: AUDIO CRITICAL. Muzzle flash often invisible in daylight (1-2 frames). Acoustic gunshot detection provides reliable trigger; video provides attribution.
A10: UC-009 | B10: Medical Casualty Detection During Live Exercise | C10: VISUAL-PRIMARY: Fall and posture detection are visual. AUDIO-ENHANCED: 'Man down' calls and sudden silence provide secondary confirmation.
A11: UC-021 | B11: Room Clearing Sequence Deviation Detection | C11: VISUAL-PRIMARY: Movement and sequence are visual. AUDIO-ENHANCED: Verbal callouts ('clear left', 'room clear') are integral to the drill.
A12: UC-023 | B12: Weapon Discharge in Non-Authorized MOUT Zone | C12: AUDIO ESSENTIAL indoors. Blank rounds produce minimal visual signature. Acoustic detection reliably captures the report.
A13: UC-025 | B13: Non-Combatant / Role-Player Safety in MOUT | C13: VISUAL-PRIMARY: Role-player tracking via markers is visual. AUDIO-ENHANCED: Gunshot detection confirms blank fire near role-players.
A14: UC-037 | B14: Incident Replay and Timeline Reconstruction | C14: AUDIO VALUABLE. Visual provides spatial picture; audio provides timeline anchoring - gunshot timing, verbal commands, radio calls, and contextual sound.
A15: UC-042 | B15: Drone/UAS Operational Safety Monitoring | C15: AUDIO VALUABLE. Small UAS (<2kg) extremely hard to detect visually beyond 100-200m. Drone motors have distinct acoustic signatures at greater range. Audio alerts; visual confirms.
A16: UC-044 | B16: Pyrotechnics / Grenade Range Safety Monitoring | C16: AUDIO CRITICAL. Camera flash-blinded at detonation. Acoustic confirmation is definitive. Misfire detection (absence of bang) more reliable via audio.
A17: UC-047 | B17: Reaction Time Measurement on Target Exposure | C17: VISUAL-PRIMARY: Target exposure is visual. AUDIO-ENHANCED: Acoustic shot timing resolves to ms vs ±33ms from video at 30fps.
A18: UC-048 | B18: Communication Gesture Recognition | C18: VISUAL-PRIMARY: Gesture recognition is visual. AUDIO-ENHANCED: Verbal acknowledgments ('roger', 'moving') complete the communication assessment.
A19: UC-049 | B19: Tactical Bound Timing and Coordination Assessment | C19: VISUAL-PRIMARY: Movement tracking is visual. AUDIO-ENHANCED: Detecting covering fire (esp. blank rounds) via audio is far more reliable.
A20: UC-050 | B20: After-Action Review Automated Highlight Generation | C20: AUDIO VALUABLE. Visual provides events; verbal commands and radio traffic are essential context for meaningful AAR.

Sheet Projects
B2: Project Name | C2: Policies
B3: Project A | C3: Policy - UC-001
C4: Policy - UC-002
C5: Policy - UC-003

Sheet Policy - TEMPLATE
A1: ▼ TYPE THE UC ID IN THE YELLOW CELL BELOW - EVERYTHING ELSE AUTO-FILLS ▼
B2: UC ID ↓
A4: IDENTIFICATION | B4: Use Case Name | C4: {=IFERROR(INDEX('Use Case Library'!B:T,MATCH(C2,'Use Case Library'!B:B,0),4),"")}
B5: Group | C5: {=IFERROR(INDEX('Use Case Library'!B:T,MATCH(C2,'Use Case Library'!B:B,0),2),"")}
B6: Category | C6: {=IFERROR(INDEX('Use Case Library'!B:T,MATCH(C2,'Use Case Library'!B:B,0),3),"")}
B7: Priority | C7: {=IFERROR(INDEX('Use Case Library'!B:T,MATCH(C2,'Use Case Library'!B:B,0),12),"")}
B8: Status | C8: {=IFERROR(INDEX('Use Case Library'!B:T,MATCH(C2,'Use Case Library'!B:B,0),13),"")}
B9: Detection Modality | C9: {=IFERROR(INDEX('Use Case Library'!B:T,MATCH(C2,'Use Case Library'!B:B,0),16),"")}
B10: Last Updated
A11: CONTEXT (auto-pulled - edit in Use Case Library, not here)
B12: Description | C12: {=IFERROR(INDEX('Use Case Library'!B:T,MATCH(C2,'Use Case Library'!B:B,0),5),"")}
B13: User Intent | C13: {=IFERROR(INDEX('Use Case Library'!B:T,MATCH(C2,'Use Case Library'!B:B,0),6),"")}
B14: Trigger / Detection Method | C14: {=IFERROR(INDEX('Use Case Library'!B:T,MATCH(C2,'Use Case Library'!B:B,0),7),"")}
B15: Key Behaviours to Track | C15: {=IFERROR(INDEX('Use Case Library'!B:T,MATCH(C2,'Use Case Library'!B:B,0),8),"")}
B16: Desired Outcome | C16: {=IFERROR(INDEX('Use Case Library'!B:T,MATCH(C2,'Use Case Library'!B:B,0),9),"")}
B17: Current Handling | C17: {=IFERROR(INDEX('Use Case Library'!B:T,MATCH(C2,'Use Case Library'!B:B,0),10),"")}
B18: Edge Cases (from library) | C18: {=IFERROR(INDEX('Use Case Library'!B:T,MATCH(C2,'Use Case Library'!B:B,0),11),"")}
B19: Dependencies | C19: {=IFERROR(INDEX('Use Case Library'!B:T,MATCH(C2,'Use Case Library'!B:B,0),15),"")}
B20: Current Policy Summary | C20: {=IFERROR(INDEX('Use Case Library'!B:T,MATCH(C2,'Use Case Library'!B:B,0),14),"")}
B21: Modality Rationale | C21: {=IFERROR(INDEX('Use Case Library'!B:T,MATCH(C2,'Use Case Library'!B:B,0),17),"")}
A22: DECISION LOGIC (fill manually - core deliverable)
B23: Step 1: Detection | C23: What signals indicate this use case is active? Classifiers, keywords, flags, thresholds.
B24: Step 2: Classification | C24: How do you determine severity or sub-type? What categories exist?
B25: Step 3: Response Selection | C25: What response strategy maps to each classification?
B26: Step 4: Execution | C26: What exactly does the system do? Be specific - templates, actions, tone.
B27: Step 5: Validation | C27: How verify the response was appropriate? Pre/post-delivery checks?
B28: Step 6: Follow-up | C28: What happens after initial response? Loops, escalation, closure.
B29: Algorithm (pseudocode / decision tree) | C29: Write complete if/then/else logic. IF [condition] THEN → [action] ELSE IF [condition] THEN → [action] ELSE → [default] END
A30: METRICS | B30: Success Metrics / KPIs | C30: How measure this is handled well?
B31: Failure Indicators | C31: What signals the policy is failing?
B32: Evaluation Method | C32: A/B test, manual review, automated checks?
A33: DETAILED EDGE CASES | B33: Edge Case 1
B34: → Handling
B35: Edge Case 2
B36: → Handling
B37: Edge Case 3
B38: → Handling
B39: Edge Case 4
B40: → Handling
A41: TEST CASES (input → expected → rationale)
...

Sheet Policy - UC-001
A1: ▼ TYPE THE UC ID IN THE YELLOW CELL BELOW - EVERYTHING ELSE AUTO-FILLS ▼
B2: UC ID ↓ | C2: UC-003
A4: IDENTIFICATION | B4: Use Case Name | C4: {=IFERROR(INDEX('Use Case Library'!B:T,MATCH(C2,'Use Case Library'!B:B,0),4),"")} -> Weapon Left Unattended Detection
B5: Group | C5: {=IFERROR(INDEX('Use Case Library'!B:T,MATCH(C2,'Use Case Library'!B:B,0),2),"")} -> A
B6: Category | C6: {=IFERROR(INDEX('Use Case Library'!B:T,MATCH(C2,'Use Case Library'!B:B,0),3),"")} -> Core Safety | E6: Project1
B7: Priority | C7: {=IFERROR(INDEX('Use Case Library'!B:T,MATCH(C2,'Use Case Library'!B:B,0),12),"")} -> P1 - High | F7: Policy 1
B8: Status | C8: {=IFERROR(INDEX('Use Case Library'!B:T,MATCH(C2,'Use Case Library'!B:B,0),13),"")} -> Not Started | F8: Policy 2 | G8: Configuration A (15 degrees, muzzle pointing direction)
B9: Detection Modality | C9: {=IFERROR(INDEX('Use Case Library'!B:T,MATCH(C2,'Use Case Library'!B:B,0),16),"")}
B10: Last Updated | C10: 46133 | E10: Project2
A11: REQUIREMENTS CONTEXT (auto-pulled - edit in Use Case Library, not here) | F11: Policy 2 | G11: Configuration B (10 degrees, muzzle pointing direction)
B12: Description | C12: {=IFERROR(INDEX('Use Case Library'!B:T,MATCH(C2,'Use Case Library'!B:B,0),5),"")} -> Detects a weapon stationary and not associated with any person in proximity - on ground, bench, or firing point with no one nearby - beyond a defined time threshold. | F12: Policy 3
B13: User Intent | C13: {=IFERROR(INDEX('Use Case Library'!B:T,MATCH(C2,'Use Case Library'!B:B,0),6),"")} -> No weapon should ever be left unsecured and unattended on a range.
B14: Trigger / Detection Method | C14: {=IFERROR(INDEX('Use Case Library'!B:T,MATCH(C2,'Use Case Library'!B:B,0),7),"")} -> Weapon-shaped object detection + human proximity check within defined radius + time-based trigger (e.g., 30s with no person within 2m). Focus on both day and night modes.
B15: Key Behaviours to Track | C15: {=IFERROR(INDEX('Use Case Library'!B:T,MATCH(C2,'Use Case Library'!B:B,0),8),"")} -> 1) Time weapon is unattended before detection 2) Distance to nearest person when flagged 3) Location context (firing point vs walkway vs rest area) 4) False positive rate (training props, weapon racks)
B16: Desired Outcome | C16: {=IFERROR(INDEX('Use Case Library'!B:T,MATCH(C2,'Use Case Library'!B:B,0),9),"")} -> Alert to nearest safety officer with weapon location, camera feed, and duration unattended. By default: If no external system integration is needed, it will then route the notification and alert to Accel.
B17: Current Handling | C17: {=IFERROR(INDEX('Use Case Library'!B:T,MATCH(C2,'Use Case Library'!B:B,0),10),"")} -> Discovered during physical checks or when someone reports a found weapon.
B18: Edge Cases (from library) | C18: {=IFERROR(INDEX('Use Case Library'!B:T,MATCH(C2,'Use Case Library'!B:B,0),11),"")} -> - Weapons deliberately placed in racks (authorised) - Training props / dummy weapons - Weapon placed down momentarily during drill change - Partial occlusion (under bench, behind bag)
B19: Dependencies | C19: {=IFERROR(INDEX('Use Case Library'!B:T,MATCH(C2,'Use Case Library'!B:B,0),15),"")} -> UC-008
B20: Current Policy Summary | C20: {=IFERROR(INDEX('Use Case Library'!B:T,MATCH(C2,'Use Case Library'!B:B,0),14),"")} -> Weapon Left Unattended IF weapon detected with no person within 2m radius for > 30s → ALERT to nearest safety officer. IF weapon is in designated rack/storage zone → suppress (authorised placement). IF weapon unattended > 120s anywhere → escalate to URGENT. Reset timer when any person enters 2m radius.
B21: Modality Rationale | C21: {=IFERROR(INDEX('Use Case Library'!B:T,MATCH(C2,'Use Case Library'!B:B,0),17),"")} -> Visual Only
A22: INFLUENCED TECHNOLOGIES REFERENCE
B23: AAAAAAA | C23: www.aaaa.com
A25: DECISION LOGIC (fill manually - core deliverable)
B26: Step 1: Detection | C26: The system needs to detect two things simultaneously: (a) the weapon's muzzle direction vector, and (b) the positions of all other persons in the frame. The muzzle vector is derived from weapon pose estimation, identifying the barrel axis from the receiver to muzzle tip. This requires the weapon to be at least partially visible. The system calculates the angular relationship between the muzzle vector and every detected person within a defined range (e.g., 30m forward arc). A "sweep" event is triggered when the muzzle-to-person angle falls below a threshold, I'd start at 15° cone, but this needs calibration with real range footage. Detection runs continuously at frame rate on all firing line cameras. | E26: CV Team to fill and maintain.
B27: Step 2: Classification | C27: Not all sweeps are equal. Classification axes: Duration: Transient (<2s) vs Sustained (≥2s). Transient sweeps happen during legitimate weapon transitions, going from slung to ready, changing firing position, or moving along the firing line. Sustained sweeps indicate either negligence or loss of awareness. Context: Firer stationary vs in motion. A sweep during movement (transitioning between positions) is less severe than a sweep while stationary. Proximity: How close is the swept person? A sweep across someone 2m away is far more dangerous than across someone 25m away at the end of the line. Weapon state: If weapon is in SLUNG state (from UC-008), muzzle may point near others but with no intent, lower severity. If weapon is in AIMED or HIGH-READY, any sweep is high severity. Classification matrix: CRITICAL: Sustained + stationary + aimed/high-ready + person within 3m HIGH: Sustained + any context + person within 5m MEDIUM: Transient + repeated (2nd+ occurrence in session) OR sustained + person beyond 10m LOW: Single transient during movement transition
B28: Step 3: Response Selection | C28: CRITICAL → Immediate audio/visual alert to Range Safety Officer (RSO) + auto-capture screenshot + recommend individual ceasefire for that position HIGH → Immediate alert to RSO + auto-capture. No ceasefire recommendation but RSO briefed to intervene directly. MEDIUM → Alert queued (non-interrupting notification to RSO). Logged for post-session review and UC-010 pattern tracking. LOW → Log only. No real-time alert. Feeds into UC-010 aggregate.
B29: Step 4: Execution | C29: On CRITICAL/HIGH trigger: (a) System freezes the relevant camera frame with muzzle vector overlay drawn on image (showing the firer, the vector, and the swept person highlighted) (b) Alert pushed to RSO tablet/screen: "MUZZLE VIOLATION — Lane [X], [severity], [firer description by position], [swept person description by position], [duration]s" (c) 5-second video clip buffered (2s before, 3s after event start) and attached to alert (d) If CRITICAL: audible alarm tone on RSO device + text overlay on range control display (e) Event logged with: timestamp, camera ID, firer position, swept person position, angle, duration, weapon state, classification On MEDIUM/LOW: (a) Event logged with same data fields (b) MEDIUM events appear in RSO's notification queue (reviewable between serials) (c) LOW events visible only in post-session reports
B30: Step 5: Validation | C30: Pre-delivery: Before alerting RSO, system performs a 0.5s confirmation check - is the detection sustained across multiple frames? Single-frame detections are suppressed (likely noise). This prevents alert fatigue from momentary classification errors. Post-delivery: RSO has a "Confirm / Dismiss" option on each alert. Confirmed alerts feed into UC-010. Dismissed alerts are logged as false positives and fed back for model retraining. Track the confirm/dismiss ratio - if dismiss rate > 30%, the threshold needs recalibration.
B31: Step 6: Follow-up | C31: (a) After any CRITICAL alert: system flags the individual for enhanced monitoring for remainder of session (tighter thresholds, lower duration requirement for alert) (b) After session: generate per-individual safety report showing all muzzle events (severity, frequency, trend) (c) If pattern detected across session (≥3 events, any severity): auto-generate UC-010 referral (d) RSO can mark an individual as "under remedial supervision" which persists across sessions
